Workbook

Sheet Tracker
A1: Riverstone Supplies — Monthly sales tracker, 2025
A2: Net revenue = quantity × unit price × (1 − discount %). Cancelled orders excluded. Source: ERP export.
A4: month | B4: target | C4: orders | D4: net_revenue | E4: pct_of_target | F4: vs_prev_month | G4: status
A5: =Targets!A2 | B5: =Targets!B2 | C5: =SUMIFS(Data!$L$2:$L$331,Data!$K$2:$K$331,A5,Data!$H$2:$H$331,"<>Cancelled") | D5: =SUMIFS(Data!$J$2:$J$331,Data!$B$2:$B$331,">="&A5,Data!$B$2:$B$331,"<="&EOMONTH(A5,0),Data!$H$2:$H$331,"<>Cancelled") | E5: =D5/B5 | G5: =IF(D5>=B5,"On target","Below target")
A6: =Targets!A3 | B6: =Targets!B3 | C6: =SUMIFS(Data!$L$2:$L$331,Data!$K$2:$K$331,A6,Data!$H$2:$H$331,"<>Cancelled") | D6: =SUMIFS(Data!$J$2:$J$331,Data!$B$2:$B$331,">="&A6,Data!$B$2:$B$331,"<="&EOMONTH(A6,0),Data!$H$2:$H$331,"<>Cancelled") | E6: =D6/B6 | F6: =D6/D5-1 | G6: =IF(D6>=B6,"On target","Below target")
A7: =Targets!A4 | B7: =Targets!B4 | C7: =SUMIFS(Data!$L$2:$L$331,Data!$K$2:$K$331,A7,Data!$H$2:$H$331,"<>Cancelled") | D7: =SUMIFS(Data!$J$2:$J$331,Data!$B$2:$B$331,">="&A7,Data!$B$2:$B$331,"<="&EOMONTH(A7,0),Data!$H$2:$H$331,"<>Cancelled") | E7: =D7/B7 | F7: =D7/D6-1 | G7: =IF(D7>=B7,"On target","Below target")
A8: =Targets!A5 | B8: =Targets!B5 | C8: =SUMIFS(Data!$L$2:$L$331,Data!$K$2:$K$331,A8,Data!$H$2:$H$331,"<>Cancelled") | D8: =SUMIFS(Data!$J$2:$J$331,Data!$B$2:$B$331,">="&A8,Data!$B$2:$B$331,"<="&EOMONTH(A8,0),Data!$H$2:$H$331,"<>Cancelled") | E8: =D8/B8 | F8: =D8/D7-1 | G8: =IF(D8>=B8,"On target","Below target")
A9: =Targets!A6 | B9: =Targets!B6 | C9: =SUMIFS(Data!$L$2:$L$331,Data!$K$2:$K$331,A9,Data!$H$2:$H$331,"<>Cancelled") | D9: =SUMIFS(Data!$J$2:$J$331,Data!$B$2:$B$331,">="&A9,Data!$B$2:$B$331,"<="&EOMONTH(A9,0),Data!$H$2:$H$331,"<>Cancelled") | E9: =D9/B9 | F9: =D9/D8-1 | G9: =IF(D9>=B9,"On target","Below target")
A10: =Targets!A7 | B10: =Targets!B7 | C10: =SUMIFS(Data!$L$2:$L$331,Data!$K$2:$K$331,A10,Data!$H$2:$H$331,"<>Cancelled") | D10: =SUMIFS(Data!$J$2:$J$331,Data!$B$2:$B$331,">="&A10,Data!$B$2:$B$331,"<="&EOMONTH(A10,0),Data!$H$2:$H$331,"<>Cancelled") | E10: =D10/B10 | F10: =D10/D9-1 | G10: =IF(D10>=B10,"On target","Below target")
A11: =Targets!A8 | B11: =Targets!B8 | C11: =SUMIFS(Data!$L$2:$L$331,Data!$K$2:$K$331,A11,Data!$H$2:$H$331,"<>Cancelled") | D11: =SUMIFS(Data!$J$2:$J$331,Data!$B$2:$B$331,">="&A11,Data!$B$2:$B$331,"<="&EOMONTH(A11,0),Data!$H$2:$H$331,"<>Cancelled") | E11: =D11/B11 | F11: =D11/D10-1 | G11: =IF(D11>=B11,"On target","Below target")
A12: =Targets!A9 | B12: =Targets!B9 | C12: =SUMIFS(Data!$L$2:$L$331,Data!$K$2:$K$331,A12,Data!$H$2:$H$331,"<>Cancelled") | D12: =SUMIFS(Data!$J$2:$J$331,Data!$B$2:$B$331,">="&A12,Data!$B$2:$B$331,"<="&EOMONTH(A12,0),Data!$H$2:$H$331,"<>Cancelled") | E12: =D12/B12 | F12: =D12/D11-1 | G12: =IF(D12>=B12,"On target","Below target")
A13: =Targets!A10 | B13: =Targets!B10 | C13: =SUMIFS(Data!$L$2:$L$331,Data!$K$2:$K$331,A13,Data!$H$2:$H$331,"<>Cancelled") | D13: =SUMIFS(Data!$J$2:$J$331,Data!$B$2:$B$331,">="&A13,Data!$B$2:$B$331,"<="&EOMONTH(A13,0),Data!$H$2:$H$331,"<>Cancelled") | E13: =D13/B13 | F13: =D13/D12-1 | G13: =IF(D13>=B13,"On target","Below target")
A14: =Targets!A11 | B14: =Targets!B11 | C14: =SUMIFS(Data!$L$2:$L$331,Data!$K$2:$K$331,A14,Data!$H$2:$H$331,"<>Cancelled") | D14: =SUMIFS(Data!$J$2:$J$331,Data!$B$2:$B$331,">="&A14,Data!$B$2:$B$331,"<="&EOMONTH(A14,0),Data!$H$2:$H$331,"<>Cancelled") | E14: =D14/B14 | F14: =D14/D13-1 | G14: =IF(D14>=B14,"On target","Below target")
A15: =Targets!A12 | B15: =Targets!B12 | C15: =SUMIFS(Data!$L$2:$L$331,Data!$K$2:$K$331,A15,Data!$H$2:$H$331,"<>Cancelled") | D15: =SUMIFS(Data!$J$2:$J$331,Data!$B$2:$B$331,">="&A15,Data!$B$2:$B$331,"<="&EOMONTH(A15,0),Data!$H$2:$H$331,"<>Cancelled") | E15: =D15/B15 | F15: =D15/D14-1 | G15: =IF(D15>=B15,"On target","Below target")
A16: =Targets!A13 | B16: =Targets!B13 | C16: =SUMIFS(Data!$L$2:$L$331,Data!$K$2:$K$331,A16,Data!$H$2:$H$331,"<>Cancelled") | D16: =SUMIFS(Data!$J$2:$J$331,Data!$B$2:$B$331,">="&A16,Data!$B$2:$B$331,"<="&EOMONTH(A16,0),Data!$H$2:$H$331,"<>Cancelled") | E16: =D16/B16 | F16: =D16/D15-1 | G16: =IF(D16>=B16,"On target","Below target")
A17: Total | B17: =SUM(B5:B16) | C17: =SUM(C5:C16) | D17: =SUM(D5:D16) | E17: =D17/B17
A19: Check: total net revenue on the Data sheet (non-cancelled) | D19: =SUMIFS(Data!$J$2:$J$331,Data!$H$2:$H$331,"<>Cancelled")
A20: Check: difference (must be 0) | D20: =D17-D19

Sheet Reps
A1: sales_rep | B1: orders | C1: net_revenue | D1: share_of_total | F1: Pick a rep: | G1: Neha Kulkarni
A2: Neha Kulkarni | B2: =SUMIFS(Data!$L$2:$L$331,Data!$I$2:$I$331,A2,Data!$H$2:$H$331,"<>Cancelled") | C2: =SUMIFS(Data!$J$2:$J$331,Data!$I$2:$I$331,A2,Data!$H$2:$H$331,"<>Cancelled") | D2: =C2/$C$6 | F2: Net revenue: | G2: =SUMIFS(Data!$J$2:$J$331,Data!$I$2:$I$331,G1,Data!$H$2:$H$331,"<>Cancelled")
A3: Rahul Mehta | B3: =SUMIFS(Data!$L$2:$L$331,Data!$I$2:$I$331,A3,Data!$H$2:$H$331,"<>Cancelled") | C3: =SUMIFS(Data!$J$2:$J$331,Data!$I$2:$I$331,A3,Data!$H$2:$H$331,"<>Cancelled") | D3: =C3/$C$6
A4: Farah Khan | B4: =SUMIFS(Data!$L$2:$L$331,Data!$I$2:$I$331,A4,Data!$H$2:$H$331,"<>Cancelled") | C4: =SUMIFS(Data!$J$2:$J$331,Data!$I$2:$I$331,A4,Data!$H$2:$H$331,"<>Cancelled") | D4: =C4/$C$6
A5: (no rep) | B5: =SUMIFS(Data!$L$2:$L$331,Data!$I$2:$I$331,"",Data!$H$2:$H$331,"<>Cancelled") | C5: =SUMIFS(Data!$J$2:$J$331,Data!$I$2:$I$331,"",Data!$H$2:$H$331,"<>Cancelled") | D5: =C5/$C$6
A6: Total | B6: =SUM(B2:B5) | C6: =SUM(C2:C5) | D6: =SUM(D2:D5)
A9: segment | B9: orders | C9: net_revenue | D9: share_of_total
A10: Retail | B10: =SUMIFS(Data!$L$2:$L$331,Data!$N$2:$N$331,A10,Data!$H$2:$H$331,"<>Cancelled") | C10: =SUMIFS(Data!$J$2:$J$331,Data!$N$2:$N$331,A10,Data!$H$2:$H$331,"<>Cancelled") | D10: =C10/SUM($C$10:$C$12)
A11: Hospitality | B11: =SUMIFS(Data!$L$2:$L$331,Data!$N$2:$N$331,A11,Data!$H$2:$H$331,"<>Cancelled") | C11: =SUMIFS(Data!$J$2:$J$331,Data!$N$2:$N$331,A11,Data!$H$2:$H$331,"<>Cancelled") | D11: =C11/SUM($C$10:$C$12)
A12: Wholesale | B12: =SUMIFS(Data!$L$2:$L$331,Data!$N$2:$N$331,A12,Data!$H$2:$H$331,"<>Cancelled") | C12: =SUMIFS(Data!$J$2:$J$331,Data!$N$2:$N$331,A12,Data!$H$2:$H$331,"<>Cancelled") | D12: =C12/SUM($C$10:$C$12)

Sheet Data
A1: order_id | B1: order_date | C1: customer_code | D1: product_id | E1: quantity | F1: unit_price | G1: discount_pct | H1: status | I1: sales_rep | J1: net_revenue | K1: month_start | L1: first_line_of_order | M1: customer_name | N1: segment
A2: 10001 | B2: 45659 | C2: 0002 | D2: 108 | E2: 10 | F2: 290 | G2: 0 | H2: Delivered | I2: Neha Kulkarni | J2: =E2*F2*(1-G2/100) | K2: =DATE(YEAR(B2),MONTH(B2),1) | L2: =IF(COUNTIF($A$2:A2,A2)=1,1,0) | M2: =_xlfn.XLOOKUP(C2,Customers!$A$2:$A$25,Customers!$B$2:$B$25,"not found") | N2: =_xlfn.XLOOKUP(C2,Customers!$A$2:$A$25,Customers!$D$2:$D$25,"not found")
A3: 10002 | B3: 45662 | C3: 0003 | D3: 107 | E3: 55 | F3: 380 | G3: 0 | H3: Delivered | I3: Farah Khan | J3: =E3*F3*(1-G3/100) | K3: =DATE(YEAR(B3),MONTH(B3),1) | L3: =IF(COUNTIF($A$2:A3,A3)=1,1,0) | M3: =_xlfn.XLOOKUP(C3,Customers!$A$2:$A$25,Customers!$B$2:$B$25,"not found") | N3: =_xlfn.XLOOKUP(C3,Customers!$A$2:$A$25,Customers!$D$2:$D$25,"not found")
A4: 10003 | B4: 45669 | C4: 0005 | D4: 101 | E4: 25 | F4: 430 | G4: 0 | H4: Delivered | I4: Rahul Mehta | J4: =E4*F4*(1-G4/100) | K4: =DATE(YEAR(B4),MONTH(B4),1) | L4: =IF(COUNTIF($A$2:A4,A4)=1,1,0) | M4: =_xlfn.XLOOKUP(C4,Customers!$A$2:$A$25,Customers!$B$2:$B$25,"not found") | N4: =_xlfn.XLOOKUP(C4,Customers!$A$2:$A$25,Customers!$D$2:$D$25,"not found")
A5: 10003 | B5: 45669 | C5: 0005 | D5: 102 | E5: 45 | F5: 750 | G5: 5 | H5: Delivered | I5: Rahul Mehta | J5: =E5*F5*(1-G5/100) | K5: =DATE(YEAR(B5),MONTH(B5),1) | L5: =IF(COUNTIF($A$2:A5,A5)=1,1,0) | M5: =_xlfn.XLOOKUP(C5,Customers!$A$2:$A$25,Customers!$B$2:$B$25,"not found") | N5: =_xlfn.XLOOKUP(C5,Customers!$A$2:$A$25,Customers!$D$2:$D$25,"not found")
A6: 10003 | B6: 45669 | C6: 0005 | D6: 108 | E6: 10 | F6: 290 | G6: 0 | H6: Delivered | I6: Rahul Mehta | J6: =E6*F6*(1-G6/100) | K6: =DATE(YEAR(B6),MONTH(B6),1) | L6: =IF(COUNTIF($A$2:A6,A6)=1,1,0) | M6: =_xlfn.XLOOKUP(C6,Customers!$A$2:$A$25,Customers!$B$2:$B$25,"not found") | N6: =_xlfn.XLOOKUP(C6,Customers!$A$2:$A$25,Customers!$D$2:$D$25,"not found")
A7: 10004 | B7: 45670 | C7: 0005 | D7: 101 | E7: 40 | F7: 430 | G7: 0 | H7: Delivered | I7: Rahul Mehta | J7: =E7*F7*(1-G7/100) | K7: =DATE(YEAR(B7),MONTH(B7),1) | L7: =IF(COUNTIF($A$2:A7,A7)=1,1,0) | M7: =_xlfn.XLOOKUP(C7,Customers!$A$2:$A$25,Customers!$B$2:$B$25,"not found") | N7: =_xlfn.XLOOKUP(C7,Customers!$A$2:$A$25,Customers!$D$2:$D$25,"not found")
A8: 10004 | B8: 45670 | C8: 0005 | D8: 102 | E8: 15 | F8: 750 | G8: 5 | H8: Delivered | I8: Rahul Mehta | J8: =E8*F8*(1-G8/100) | K8: =DATE(YEAR(B8),MONTH(B8),1) | L8: =IF(COUNTIF($A$2:A8,A8)=1,1,0) | M8: =_xlfn.XLOOKUP(C8,Customers!$A$2:$A$25,Customers!$B$2:$B$25,"not found") | N8: =_xlfn.XLOOKUP(C8,Customers!$A$2:$A$25,Customers!$D$2:$D$25,"not found")
A9: 10005 | B9: 45677 | C9: 0003 | D9: 101 | E9: 15 | F9: 430 | G9: 5 | H9: Delivered | I9: Farah Khan | J9: =E9*F9*(1-G9/100) | K9: =DATE(YEAR(B9),MONTH(B9),1) | L9: =IF(COUNTIF($A$2:A9,A9)=1,1,0) | M9: =_xlfn.XLOOKUP(C9,Customers!$A$2:$A$25,Customers!$B$2:$B$25,"not found") | N9: =_xlfn.XLOOKUP(C9,Customers!$A$2:$A$25,Customers!$D$2:$D$25,"not found")
A10: 10006 | B10: 45678 | C10: 0004 | D10: 102 | E10: 25 | F10: 750 | G10: 5 | H10: Delivered | I10: Rahul Mehta | J10: =E10*F10*(1-G10/100) | K10: =DATE(YEAR(B10),MONTH(B10),1) | L10: =IF(COUNTIF($A$2:A10,A10)=1,1,0) | M10: =_xlfn.XLOOKUP(C10,Customers!$A$2:$A$25,Customers!$B$2:$B$25,"not found") | N10: =_xlfn.XLOOKUP(C10,Customers!$A$2:$A$25,Customers!$D$2:$D$25,"not found")
A11: 10007 | B11: 45681 | C11: 0001 | D11: 101 | E11: 45 | F11: 430 | G11: 0 | H11: Delivered | I11: Neha Kulkarni | J11: =E11*F11*(1-G11/100) | K11: =DATE(YEAR(B11),MONTH(B11),1) | L11: =IF(COUNTIF($A$2:A11,A11)=1,1,0) | M11: =_xlfn.XLOOKUP(C11,Customers!$A$2:$A$25,Customers!$B$2:$B$25,"not found") | N11: =_xlfn.XLOOKUP(C11,Customers!$A$2:$A$25,Customers!$D$2:$D$25,"not found")
A12: 10007 | B12: 45681 | C12: 0001 | D12: 102 | E12: 20 | F12: 750 | G12: 0 | H12: Delivered | I12: Neha Kulkarni | J12: =E12*F12*(1-G12/100) | K12: =DATE(YEAR(B12),MONTH(B12),1) | L12: =IF(COUNTIF($A$2:A12,A12)=1,1,0) | M12: =_xlfn.XLOOKUP(C12,Customers!$A$2:$A$25,Customers!$B$2:$B$25,"not found") | N12: =_xlfn.XLOOKUP(C12,Customers!$A$2:$A$25,Customers!$D$2:$D$25,"not found")
A13: 10007 | B13: 45681 | C13: 0001 | D13: 108 | E13: 20 | F13: 290 | G13: 0 | H13: Delivered | I13: Neha Kulkarni | J13: =E13*F13*(1-G13/100) | K13: =DATE(YEAR(B13),MONTH(B13),1) | L13: =IF(COUNTIF($A$2:A13,A13)=1,1,0) | M13: =_xlfn.XLOOKUP(C13,Customers!$A$2:$A$25,Customers!$B$2:$B$25,"not found") | N13: =_xlfn.XLOOKUP(C13,Customers!$A$2:$A$25,Customers!$D$2:$D$25,"not found")
... A29: 10014 | B29: 45705 | C29: 0007 | D29: 102 | E29: 25 | F29: 750 | G29: 8 | H29: Delivered | I29: Farah Khan | J29: =E29*F29*(1-G29/100) | K29: =DATE(YEAR(B29),MONTH(B29),1) | L29: =IF(COUNTIF($A$2:A29,A29)=1,1,0) | M29: =_xlfn.XLOOKUP(C29,Customers!$A$2:$A$25,Customers!$B$2:$B$25,"not found") | N29: =_xlfn.XLOOKUP(C29,Customers!$A$2:$A$25,Customers!$D$2:$D$25,"not found")
A30: 10015 | B30: 45708 | C30: 0006 | D30: 108 | E30: 20 | F30: 290 | G30: 0 | H30: Delivered | J30: =E30*F30*(1-G30/100) | K30: =DATE(YEAR(B30),MONTH(B30),1) | L30: =IF(COUNTIF($A$2:A30,A30)=1,1,0) | M30: =_xlfn.XLOOKUP(C30,Customers!$A$2:$A$25,Customers!$B$2:$B$25,"not found") | N30: =_xlfn.XLOOKUP(C30,Customers!$A$2:$A$25,Customers!$D$2:$D$25,"not found")
A31: 10016 | B31: 45708 | C31: 0012 | D31: 101 | E31: 25 | F31: 430 | G31: 0 | H31: Delivered | I31: Neha Kulkarni | J31: =E31*F31*(1-G31/100) | K31: =DATE(YEAR(B31),MONTH(B31),1) | L31: =IF(COUNTIF($A$2:A31,A31)=1,1,0) | M31: =_xlfn.XLOOKUP(C31,Customers!$A$2:$A$25,Customers!$B$2:$B$25,"not found") | N31: =_xlfn.XLOOKUP(C31,Customers!$A$2:$A$25,Customers!$D$2:$D$25,"not found")
A32: 10016 | B32: 45708 | C32: 0012 | D32: 103 | E32: 50 | F32: 115 | G32: 5 | H32: Delivered | I32: Neha Kulkarni | J32: =E32*F32*(1-G32/100) | K32: =DATE(YEAR(B32),MONTH(B32),1) | L32: =IF(COUNTIF($A$2:A32,A32)=1,1,0) | M32: =_xlfn.XLOOKUP(C32,Customers!$A$2:$A$25,Customers!$B$2:$B$25,"not found") | N32: =_xlfn.XLOOKUP(C32,Customers!$A$2:$A$25,Customers!$D$2:$D$25,"not found")
A33: 10016 | B33: 45708 | C33: 0012 | D33: 108 | E33: 30 | F33: 290 | G33: 0 | H33: Delivered | I33: Neha Kulkarni | J33: =E33*F33*(1-G33/100) | K33: =DATE(YEAR(B33),MONTH(B33),1) | L33: =IF(COUNTIF($A$2:A33,A33)=1,1,0) | M33: =_xlfn.XLOOKUP(C33,Customers!$A$2:$A$25,Customers!$B$2:$B$25,"not found") | N33: =_xlfn.XLOOKUP(C33,Customers!$A$2:$A$25,Customers!$D$2:$D$25,"not found")
A34: 10017 | B34: 45713 | C34: 0005 | D34: 107 | E34: 40 | F34: 380 | G34: 5 | H34: Delivered | I34: Rahul Mehta | J34: =E34*F34*(1-G34/100) | K34: =DATE(YEAR(B34),MONTH(B34),1) | L34: =IF(COUNTIF($A$2:A34,A34)=1,1,0) | M34: =_xlfn.XLOOKUP(C34,Customers!$A$2:$A$25,Customers!$B$2:$B$25,"not found") | N34: =_xlfn.XLOOKUP(C34,Customers!$A$2:$A$25,Customers!$D$2:$D$25,"not found")
A35: 10018 | B35: 45716 | C35: 0001 | D35: 101 | E35: 25 | F35: 430 | G35: 5 | H35: Delivered | I35: Neha Kulkarni | J35: =E35*F35*(1-G35/100) | K35: =DATE(YEAR(B35),MONTH(B35),1) | L35: =IF(COUNTIF($A$2:A35,A35)=1,1,0) | M35: =_xlfn.XLOOKUP(C35,Customers!$A$2:$A$25,Customers!$B$2:$B$25,"not found") | N35: =_xlfn.XLOOKUP(C35,Customers!$A$2:$A$25,Customers!$D$2:$D$25,"not found")
A36: 10018 | B36: 45716 | C36: 0001 | D36: 108 | E36: 15 | F36: 290 | G36: 0 | H36: Delivered | I36: Neha Kulkarni | J36: =E36*F36*(1-G36/100) | K36: =DATE(YEAR(B36),MONTH(B36),1) | L36: =IF(COUNTIF($A$2:A36,A36)=1,1,0) | M36: =_xlfn.XLOOKUP(C36,Customers!$A$2:$A$25,Customers!$B$2:$B$25,"not found") | N36: =_xlfn.XLOOKUP(C36,Customers!$A$2:$A$25,Customers!$D$2:$D$25,"not found")
A37: 10019 | B37: 45720 | C37: 0003 | D37: 103 | E37: 40 | F37: 115 | G37: 0 | H37: Delivered | I37: Farah Khan | J37: =E37*F37*(1-G37/100) | K37: =DATE(YEAR(B37),MONTH(B37),1) | L37: =IF(COUNTIF($A$2:A37,A37)=1,1,0) | M37: =_xlfn.XLOOKUP(C37,Customers!$A$2:$A$25,Customers!$B$2:$B$25,"not found") | N37: =_xlfn.XLOOKUP(C37,Customers!$A$2:$A$25,Customers!$D$2:$D$25,"not found")
A38: 10019 | B38: 45720 | C38: 0003 | D38: 107 | E38: 35 | F38: 380 | G38: 5 | H38: Delivered | I38: Farah Khan | J38: =E38*F38*(1-G38/100) | K38: =DATE(YEAR(B38),MONTH(B38),1) | L38: =IF(COUNTIF($A$2:A38,A38)=1,1,0) | M38: =_xlfn.XLOOKUP(C38,Customers!$A$2:$A$25,Customers!$B$2:$B$25,"not found") | N38: =_xlfn.XLOOKUP(C38,Customers!$A$2:$A$25,Customers!$D$2:$D$25,"not found")
A39: 10020 | B39: 45726 | C39: 0004 | D39: 101 | E39: 15 | F39: 430 | G39: 5 | H39: Delivered | I39: Rahul Mehta | J39: =E39*F39*(1-G39/100) | K39: =DATE(YEAR(B39),MONTH(B39),1) | L39: =IF(COUNTIF($A$2:A39,A39)=1,1,0) | M39: =_xlfn.XLOOKUP(C39,Customers!$A$2:$A$25,Customers!$B$2:$B$25,"not found") | N39: =_xlfn.XLOOKUP(C39,Customers!$A$2:$A$25,Customers!$D$2:$D$25,"not found")
A40: 10020 | B40: 45726 | C40: 0004 | D40: 102 | E40: 15 | F40: 750 | G40: 12 | H40: Delivered | I40: Rahul Mehta | J40: =E40*F40*(1-G40/100) | K40: =DATE(YEAR(B40),MONTH(B40),1) | L40: =IF(COUNTIF($A$2:A40,A40)=1,1,0) | M40: =_xlfn.XLOOKUP(C40,Customers!$A$2:$A$25,Customers!$B$2:$B$25,"not found") | N40: =_xlfn.XLOOKUP(C40,Customers!$A$2:$A$25,Customers!$D$2:$D$25,"not found")
A41: 10020 | B41: 45726 | C41: 0004 | D41: 105 | E41: 25 | F41: 1400 | G41: 10 | H41: Delivered | I41: Rahul Mehta | J41: =E41*F41*(1-G41/100) | K41: =DATE(YEAR(B41),MONTH(B41),1) | L41: =IF(COUNTIF($A$2:A41,A41)=1,1,0) | M41: =_xlfn.XLOOKUP(C41,Customers!$A$2:$A$25,Customers!$B$2:$B$25,"not found") | N41: =_xlfn.XLOOKUP(C41,Customers!$A$2:$A$25,Customers!$D$2:$D$25,"not found")
A42: 10021 | B42: 45734 | C42: 0005 | D42: 104 | E42: 15 | F42: 620 | G42: 0 | H42: Delivered | I42: Rahul Mehta | J42: =E42*F42*(1-G42/100) | K42: =DATE(YEAR(B42),MONTH(B42),1) | L42: =IF(COUNTIF($A$2:A42,A42)=1,1,0) | M42: =_xlfn.XLOOKUP(C42,Customers!$A$2:$A$25,Customers!$B$2:$B$25,"not found") | N42: =_xlfn.XLOOKUP(C42,Customers!$A$2:$A$25,Customers!$D$2:$D$25,"not found")
... A63: 10035 | B63: 45761 | C63: 0003 | D63: 101 | E63: 25 | F63: 430 | G63: 5 | H63: Delivered | I63: Farah Khan | J63: =E63*F63*(1-G63/100) | K63: =DATE(YEAR(B63),MONTH(B63),1) | L63: =IF(COUNTIF($A$2:A63,A63)=1,1,0) | M63: =_xlfn.XLOOKUP(C63,Customers!$A$2:$A$25,Customers!$B$2:$B$25,"not found") | N63: =_xlfn.XLOOKUP(C63,Customers!$A$2:$A$25,Customers!$D$2:$D$25,"not found")
A64: 10036 | B64: 45762 | C64: 0012 | D64: 103 | E64: 35 | F64: 115 | G64: 0 | H64: Delivered | J64: =E64*F64*(1-G64/100) | K64: =DATE(YEAR(B64),MONTH(B64),1) | L64: =IF(COUNTIF($A$2:A64,A64)=1,1,0) | M64: =_xlfn.XLOOKUP(C64,Customers!$A$2:$A$25,Customers!$B$2:$B$25,"not found") | N64: =_xlfn.XLOOKUP(C64,Customers!$A$2:$A$25,Customers!$D$2:$D$25,"not found")
A65: 10036 | B65: 45762 | C65: 0012 | D65: 104 | E65: 30 | F65: 620 | G65: 5 | H65: Delivered | J65: =E65*F65*(1-G65/100) | K65: =DATE(YEAR(B65),MONTH(B65),1) | L65: =IF(COUNTIF($A$2:A65,A65)=1,1,0) | M65: =_xlfn.XLOOKUP(C65,Customers!$A$2:$A$25,Customers!$B$2:$B$25,"not found") | N65: =_xlfn.XLOOKUP(C65,Customers!$A$2:$A$25,Customers!$D$2:$D$25,"not found")
A66: 10036 | B66: 45762 | C66: 0012 | D66: 107 | E66: 35 | F66: 380 | G66: 0 | H66: Delivered | J66: =E66*F66*(1-G66/100) | K66: =DATE(YEAR(B66),MONTH(B66),1) | L66: =IF(COUNTIF($A$2:A66,A66)=1,1,0) | M66: =_xlfn.XLOOKUP(C66,Customers!$A$2:$A$25,Customers!$B$2:$B$25,"not found") | N66: =_xlfn.XLOOKUP(C66,Customers!$A$2:$A$25,Customers!$D$2:$D$25,"not found")
A67: 10037 | B67: 45767 | C67: 0005 | D67: 101 | E67: 45 | F67: 430 | G67: 0 | H67: Delivered | I67: Rahul Mehta | J67: =E67*F67*(1-G67/100) | K67: =DATE(YEAR(B67),MONTH(B67),1) | L67: =IF(COUNTIF($A$2:A67,A67)=1,1,0) | M67: =_xlfn.XLOOKUP(C67,Customers!$A$2:$A$25,Customers!$B$2:$B$25,"not found") | N67: =_xlfn.XLOOKUP(C67,Customers!$A$2:$A$25,Customers!$D$2:$D$25,"not found")
A68: 10037 | B68: 45767 | C68: 0005 | D68: 108 | E68: 30 | F68: 290 | G68: 5 | H68: Delivered | I68: Rahul Mehta | J68: =E68*F68*(1-G68/100) | K68: =DATE(YEAR(B68),MONTH(B68),1) | L68: =IF(COUNTIF($A$2:A68,A68)=1,1,0) | M68: =_xlfn.XLOOKUP(C68,Customers!$A$2:$A$25,Customers!$B$2:$B$25,"not found") | N68: =_xlfn.XLOOKUP(C68,Customers!$A$2:$A$25,Customers!$D$2:$D$25,"not found")
A69: 10038 | B69: 45768 | C69: 0006 | D69: 107 | E69: 50 | F69: 380 | G69: 0 | H69: Delivered | J69: =E69*F69*(1-G69/100) | K69: =DATE(YEAR(B69),MONTH(B69),1) | L69: =IF(COUNTIF($A$2:A69,A69)=1,1,0) | M69: =_xlfn.XLOOKUP(C69,Customers!$A$2:$A$25,Customers!$B$2:$B$25,"not found") | N69: =_xlfn.XLOOKUP(C69,Customers!$A$2:$A$25,Customers!$D$2:$D$25,"not found")
A70: 10039 | B70: 45769 | C70: 0001 | D70: 102 | E70: 15 | F70: 750 | G70: 5 | H70: Delivered | I70: Neha Kulkarni | J70: =E70*F70*(1-G70/100) | K70: =DATE(YEAR(B70),MONTH(B70),1) | L70: =IF(COUNTIF($A$2:A70,A70)=1,1,0) | M70: =_xlfn.XLOOKUP(C70,Customers!$A$2:$A$25,Customers!$B$2:$B$25,"not found") | N70: =_xlfn.XLOOKUP(C70,Customers!$A$2:$A$25,Customers!$D$2:$D$25,"not found")
A71: 10039 | B71: 45769 | C71: 0001 | D71: 104 | E71: 35 | F71: 620 | G71: 0 | H71: Delivered | I71: Neha Kulkarni | J71: =E71*F71*(1-G71/100) | K71: =DATE(YEAR(B71),MONTH(B71),1) | L71: =IF(COUNTIF($A$2:A71,A71)=1,1,0) | M71: =_xlfn.XLOOKUP(C71,Customers!$A$2:$A$25,Customers!$B$2:$B$25,"not found") | N71: =_xlfn.XLOOKUP(C71,Customers!$A$2:$A$25,Customers!$D$2:$D$25,"not found")
A72: 10040 | B72: 45770 | C72: 0004 | D72: 108 | E72: 25 | F72: 290 | G72: 5 | H72: Delivered | I72: Rahul Mehta | J72: =E72*F72*(1-G72/100) | K72: =DATE(YEAR(B72),MONTH(B72),1) | L72: =IF(COUNTIF($A$2:A72,A72)=1,1,0) | M72: =_xlfn.XLOOKUP(C72,Customers!$A$2:$A$25,Customers!$B$2:$B$25,"not found") | N72: =_xlfn.XLOOKUP(C72,Customers!$A$2:$A$25,Customers!$D$2:$D$25,"not found")
A73: 10041 | B73: 45770 | C73: 0012 | D73: 103 | E73: 35 | F73: 115 | G73: 0 | H73: Delivered | I73: Neha Kulkarni | J73: =E73*F73*(1-G73/100) | K73: =DATE(YEAR(B73),MONTH(B73),1) | L73: =IF(COUNTIF($A$2:A73,A73)=1,1,0) | M73: =_xlfn.XLOOKUP(C73,Customers!$A$2:$A$25,Customers!$B$2:$B$25,"not found") | N73: =_xlfn.XLOOKUP(C73,Customers!$A$2:$A$25,Customers!$D$2:$D$25,"not found")
A74: 10041 | B74: 45770 | C74: 0012 | D74: 108 | E74: 60 | F74: 290 | G74: 5 | H74: Delivered | I74: Neha Kulkarni | J74: =E74*F74*(1-G74/100) | K74: =DATE(YEAR(B74),MONTH(B74),1) | L74: =IF(COUNTIF($A$2:A74,A74)=1,1,0) | M74: =_xlfn.XLOOKUP(C74,Customers!$A$2:$A$25,Customers!$B$2:$B$25,"not found") | N74: =_xlfn.XLOOKUP(C74,Customers!$A$2:$A$25,Customers!$D$2:$D$25,"not found")
A75: 10042 | B75: 45772 | C75: 0007 | D75: 102 | E75: 10 | F75: 750 | G75: 5 | H75: Delivered | I75: Farah Khan | J75: =E75*F75*(1-G75/100) | K75: =DATE(YEAR(B75),MONTH(B75),1) | L75: =IF(COUNTIF($A$2:A75,A75)=1,1,0) | M75: =_xlfn.XLOOKUP(C75,Customers!$A$2:$A$25,Customers!$B$2:$B$25,"not found") | N75: =_xlfn.XLOOKUP(C75,Customers!$A$2:$A$25,Customers!$D$2:$D$25,"not found")
...

Sheet Customers
A1: customer_code | B1: customer_name | C1: city | D1: segment | E1: signup_date
A2: 0001 | B2: Sharma Hardware | C2: Mumbai | D2: Retail | E2: 45600
A3: 0002 | B3: Patel Kitchenware | C3: Ahmedabad | D3: Retail | E3: 45641
A4: 0003 | B4: Green Leaf Hotels | C4: Pune | D4: Hospitality | E4: 45543
A5: 0004 | B5: Coastal Foods | C5: Chennai | D5: Wholesale | E5: 45585
A6: 0005 | B6: Metro Mart | C6: Mumbai | D6: Retail | E6: 45648
A7: 0006 | B7: Sunrise Caterers | C7: Nagpur | D7: Hospitality | E7: 45691
A8: 0007 | B8: Northgate Distributors | C8: Delhi | D8: Wholesale | E8: 45705
A9: 0008 | B9: Blue Bay Cafe | C9: Pune | D9: Hospitality | E9: 45717
A10: 0009 | B10: Lakeview Resorts | C10: Udaipur | D10: Hospitality | E10: 45516
A11: 0010 | B11: City Needs Store | C11: Jaipur | D11: Retail | E11: 45631
A12: 0011 | B12: Harbour Traders | C12: Kochi | D12: Wholesale | E12: 45756
A13: 0012 | B13: Fresh Bowl Kitchens | C13: Bengaluru | D13: Hospitality | E13: 45708
... A25: 0024 | B25: Prime Wholesale | C25: Ahmedabad | D25: Wholesale | E25: 45971

Sheet Products
A1: product_id | B1: product_name | C1: category | D1: list_price | E1: unit_cost
A2: 101 | B2: Storage Box 10L | C2: Storage | D2: 430 | E2: 300
A3: 102 | B3: Storage Box 25L | C3: Storage | D3: 750 | E3: 540
A4: 103 | B4: Water Bottle 1L | C4: Kitchen | D4: 115 | E4: 70
A5: 104 | B5: Food Container Set | C5: Kitchen | D5: 620 | E5: 430
A6: 105 | B6: Industrial Crate | C6: Industrial | D6: 1400 | E6: 1100
A7: 106 | B7: Garden Chair | C7: Furniture | D7: 1150 | E7: 850
A8: 107 | B8: Lunch Box Set | C8: Kitchen | D8: 380 | E8: 240
A9: 108 | B9: Stackable Bin | C9: Storage | D9: 290 | E9: 190

Sheet Targets
A1: month_start | B1: target_revenue
A2: 45658 | B2: 300000
A3: 45689 | B3: 300000
A4: 45717 | B4: 320000
A5: 45748 | B5: 320000
A6: 45778 | B6: 320000
A7: 45809 | B7: 300000
A8: 45839 | B8: 280000
A9: 45870 | B9: 320000
A10: 45901 | B10: 380000
A11: 45931 | B11: 520000
A12: 45962 | B12: 500000
A13: 45992 | B13: 380000
